{
  "comments": [
    {
      "key": {
        "uuid": "PDNZbBBw",
        "filename": "gerrit-gwtui/src/main/java/com/google/gerrit/client/changes/PublishCommentScreen.java",
        "patchSetId": 2
      },
      "lineNbr": 150,
      "author": {
        "id": 1001240
      },
      "writtenOn": "2013-01-31T01:09:39Z",
      "side": 1,
      "message": "why did you put this in a local variable? Why not just inline?",
      "revId": "57048321231d386fcee93eebe086f6f096db57a3",
      "serverId": "173816e5-2b9a-37c3-8a2e-48639d4f1153",
      "unresolved": false
    },
    {
      "key": {
        "uuid": "PDBZqnKk",
        "filename": "gerrit-gwtui/src/main/java/com/google/gerrit/client/rpc/CallbackGroup.java",
        "patchSetId": 2
      },
      "lineNbr": 107,
      "author": {
        "id": 1001240
      },
      "writtenOn": "2013-01-31T01:09:39Z",
      "side": 1,
      "message": "This isn\u0027t worth the effort. If an exception happens during onSuccess just let it go up the call stack and crash the event loop.",
      "revId": "57048321231d386fcee93eebe086f6f096db57a3",
      "serverId": "173816e5-2b9a-37c3-8a2e-48639d4f1153",
      "unresolved": false
    },
    {
      "key": {
        "uuid": "PDPZeAA4",
        "filename": "gerrit-gwtui/src/main/java/com/google/gerrit/client/rpc/CallbackGroup.java",
        "patchSetId": 2
      },
      "lineNbr": 134,
      "author": {
        "id": 1001240
      },
      "writtenOn": "2013-01-31T01:09:39Z",
      "side": 1,
      "message": "This isn\u0027t worth the effort. Just let it go up the call stack and crash the event loop.",
      "revId": "57048321231d386fcee93eebe086f6f096db57a3",
      "serverId": "173816e5-2b9a-37c3-8a2e-48639d4f1153",
      "unresolved": false
    },
    {
      "key": {
        "uuid": "PDDZlmNs",
        "filename": "gerrit-gwtui/src/main/java/com/google/gerrit/client/rpc/CallbackGroup.java",
        "patchSetId": 2
      },
      "lineNbr": 140,
      "author": {
        "id": 1001240
      },
      "writtenOn": "2013-01-31T01:09:39Z",
      "side": 1,
      "message": "You do not throw the exception from onFailure(). Doing so will crash the event loop in the browser. Maybe doing it for caughtDuringOnFailure makes some sense, but do not throw the exception passed into a callback out of the callback.",
      "revId": "57048321231d386fcee93eebe086f6f096db57a3",
      "serverId": "173816e5-2b9a-37c3-8a2e-48639d4f1153",
      "unresolved": false
    }
  ]
}