{
  "comments": [
    {
      "key": {
        "uuid": "7c0c6ea2_c24afe8e",
        "filename": "/COMMIT_MSG",
        "patchSetId": 7
      },
      "lineNbr": 7,
      "author": {
        "id": 1003935
      },
      "writtenOn": "2019-07-03T10:03:20Z",
      "side": 1,
      "message": "Can we make clearer that this is about user errors, not server errors?",
      "range": {
        "startLine": 7,
        "startChar": 36,
        "endLine": 7,
        "endChar": 49
      },
      "revId": "fa0b647459d52d99a3d54372421ec46aea4f4871",
      "serverId": "173816e5-2b9a-37c3-8a2e-48639d4f1153",
      "unresolved": true
    },
    {
      "key": {
        "uuid": "b2d10c0a_8c6bd0a4",
        "filename": "/COMMIT_MSG",
        "patchSetId": 7
      },
      "lineNbr": 7,
      "author": {
        "id": 1006192
      },
      "writtenOn": "2019-07-03T10:06:06Z",
      "side": 1,
      "message": "\u003e Can we make clearer that this is about user errors, not server errors?\n\nIt\u0027s about both: when there was a server error, nothing was logged either :-(\nI\u0027ll make then a follow-up change where I raise the level to warning in case of server errors.",
      "parentUuid": "7c0c6ea2_c24afe8e",
      "range": {
        "startLine": 7,
        "startChar": 36,
        "endLine": 7,
        "endChar": 49
      },
      "revId": "fa0b647459d52d99a3d54372421ec46aea4f4871",
      "serverId": "173816e5-2b9a-37c3-8a2e-48639d4f1153",
      "unresolved": true
    },
    {
      "key": {
        "uuid": "7511ddde_1bc78caa",
        "filename": "/COMMIT_MSG",
        "patchSetId": 7
      },
      "lineNbr": 7,
      "author": {
        "id": 1003935
      },
      "writtenOn": "2019-07-03T10:10:05Z",
      "side": 1,
      "message": "\u003e It\u0027s about both: when there was a server error, nothing was logged either :-(\n\nBut that\u0027s already fixed in master, cherry-pick [1] for this?\n\n[1] https://gerrit-review.googlesource.com/c/gerrit/+/223978",
      "parentUuid": "b2d10c0a_8c6bd0a4",
      "range": {
        "startLine": 7,
        "startChar": 36,
        "endLine": 7,
        "endChar": 49
      },
      "revId": "fa0b647459d52d99a3d54372421ec46aea4f4871",
      "serverId": "173816e5-2b9a-37c3-8a2e-48639d4f1153",
      "unresolved": true
    },
    {
      "key": {
        "uuid": "d704b225_668925ba",
        "filename": "/COMMIT_MSG",
        "patchSetId": 7
      },
      "lineNbr": 7,
      "author": {
        "id": 1006192
      },
      "writtenOn": "2019-07-03T10:16:30Z",
      "side": 1,
      "message": "On [1] at the same corresponding line I see:\n\n  logger.atFinest().log(\"REST call failed: %d\", statusCode);\n\nLooks like the error is there on master also: we don\u0027t trace the exception.",
      "parentUuid": "7511ddde_1bc78caa",
      "range": {
        "startLine": 7,
        "startChar": 36,
        "endLine": 7,
        "endChar": 49
      },
      "revId": "fa0b647459d52d99a3d54372421ec46aea4f4871",
      "serverId": "173816e5-2b9a-37c3-8a2e-48639d4f1153",
      "unresolved": true
    },
    {
      "key": {
        "uuid": "92b010ef_bd7c94cd",
        "filename": "/COMMIT_MSG",
        "patchSetId": 7
      },
      "lineNbr": 7,
      "author": {
        "id": 1003935
      },
      "writtenOn": "2019-07-03T10:21:25Z",
      "side": 1,
      "message": "I\u0027m not following, handleExceptions already logs the exception for 500s, why would it need to be logged here again if it\u0027s a 500?",
      "parentUuid": "d704b225_668925ba",
      "range": {
        "startLine": 7,
        "startChar": 36,
        "endLine": 7,
        "endChar": 49
      },
      "revId": "fa0b647459d52d99a3d54372421ec46aea4f4871",
      "serverId": "173816e5-2b9a-37c3-8a2e-48639d4f1153",
      "unresolved": true
    },
    {
      "key": {
        "uuid": "118ca2aa_d88e9b4a",
        "filename": "/COMMIT_MSG",
        "patchSetId": 7
      },
      "lineNbr": 7,
      "author": {
        "id": 1006192
      },
      "writtenOn": "2019-07-03T10:25:54Z",
      "side": 1,
      "message": "\u003e I\u0027m not following, handleExceptions already logs the exception for 500s, why would it need to be logged here again if it\u0027s a 500?\n\nBecause not all internal errors are resulting in a 5xx and by swallowing what caused the non-5xx error you would never realize what\u0027s going on and fixing it.",
      "parentUuid": "92b010ef_bd7c94cd",
      "range": {
        "startLine": 7,
        "startChar": 36,
        "endLine": 7,
        "endChar": 49
      },
      "revId": "fa0b647459d52d99a3d54372421ec46aea4f4871",
      "serverId": "173816e5-2b9a-37c3-8a2e-48639d4f1153",
      "unresolved": true
    }
  ]
}